Workbook

Sheet Dashboard
A1: FRD TRACKER TEMPLATE • YOUR BOOK
A2: Blank template for personal use. Not the live Football Research Desk record. Paper 1u default $25.
A4: BETS | D4: WINS | G4: LOSSES | J4: PUSHES
A5: =COUNTA(Bets!A8:A507) | D5: =COUNTIF(Bets!L8:L507,"W") | G5: =COUNTIF(Bets!L8:L507,"L") | J5: =COUNTIF(Bets!L8:L507,"P")
A7: WIN % | D7: UNITS WON | G7: PROFIT ($) | J7: UNITS RISKED
A8: =IF((B5+G5)=0,"—",B5/(B5+G5)) | D8: =SUM(Bets!N8:N507) | G8: =SUM(Bets!O8:O507) | J8: =SUMIF(Bets!L8:L507,"<>",Bets!J8:J507)
A10: HOW THIS BOOK WORKS
A11: 1. Log only the leans you want to grade. Flyer tab is optional and off the main record.
A12: 2. PASS is not a ticket. Do not log a pass.
A13: 3. Paper unit = $25 (Settings!B3). Book = FRD. This is the public record, not personal bets.
A14: 4. Grade after the game. Tuesday Grade and recaps read THIS file.
A15: 5. The Flyer is on the Flyer tab. It is NOT in the boxes above and not on Tuesday Grade.
A17: WEEKLY ROLLUP (auto from Bets tab)
A19: Week | B19: Bets | C19: W | D19: L | E19: P | F19: Win % | G19: Units | H19: Profit $
A20: 1 | B20: =COUNTIF(Bets!B$8:B$507,A20) | C20: =COUNTIFS(Bets!B$8:B$507,A20,Bets!L$8:L$507,"W") | D20: =COUNTIFS(Bets!B$8:B$507,A20,Bets!L$8:L$507,"L") | E20: =COUNTIFS(Bets!B$8:B$507,A20,Bets!L$8:L$507,"P") | F20: =IF((C20+D20)=0,"—",C20/(C20+D20)) | G20: =SUMIF(Bets!B$8:B$507,A20,Bets!N$8:N$507) | H20: =SUMIF(Bets!B$8:B$507,A20,Bets!O$8:O$507)
A21: 2 | B21: =COUNTIF(Bets!B$8:B$507,A21) | C21: =COUNTIFS(Bets!B$8:B$507,A21,Bets!L$8:L$507,"W") | D21: =COUNTIFS(Bets!B$8:B$507,A21,Bets!L$8:L$507,"L") | E21: =COUNTIFS(Bets!B$8:B$507,A21,Bets!L$8:L$507,"P") | F21: =IF((C21+D21)=0,"—",C21/(C21+D21)) | G21: =SUMIF(Bets!B$8:B$507,A21,Bets!N$8:N$507) | H21: =SUMIF(Bets!B$8:B$507,A21,Bets!O$8:O$507)
A22: 3 | B22: =COUNTIF(Bets!B$8:B$507,A22) | C22: =COUNTIFS(Bets!B$8:B$507,A22,Bets!L$8:L$507,"W") | D22: =COUNTIFS(Bets!B$8:B$507,A22,Bets!L$8:L$507,"L") | E22: =COUNTIFS(Bets!B$8:B$507,A22,Bets!L$8:L$507,"P") | F22: =IF((C22+D22)=0,"—",C22/(C22+D22)) | G22: =SUMIF(Bets!B$8:B$507,A22,Bets!N$8:N$507) | H22: =SUMIF(Bets!B$8:B$507,A22,Bets!O$8:O$507)
A23: 4 | B23: =COUNTIF(Bets!B$8:B$507,A23) | C23: =COUNTIFS(Bets!B$8:B$507,A23,Bets!L$8:L$507,"W") | D23: =COUNTIFS(Bets!B$8:B$507,A23,Bets!L$8:L$507,"L") | E23: =COUNTIFS(Bets!B$8:B$507,A23,Bets!L$8:L$507,"P") | F23: =IF((C23+D23)=0,"—",C23/(C23+D23)) | G23: =SUMIF(Bets!B$8:B$507,A23,Bets!N$8:N$507) | H23: =SUMIF(Bets!B$8:B$507,A23,Bets!O$8:O$507)
A24: 5 | B24: =COUNTIF(Bets!B$8:B$507,A24) | C24: =COUNTIFS(Bets!B$8:B$507,A24,Bets!L$8:L$507,"W") | D24: =COUNTIFS(Bets!B$8:B$507,A24,Bets!L$8:L$507,"L") | E24: =COUNTIFS(Bets!B$8:B$507,A24,Bets!L$8:L$507,"P") | F24: =IF((C24+D24)=0,"—",C24/(C24+D24)) | G24: =SUMIF(Bets!B$8:B$507,A24,Bets!N$8:N$507) | H24: =SUMIF(Bets!B$8:B$507,A24,Bets!O$8:O$507)
A25: 6 | B25: =COUNTIF(Bets!B$8:B$507,A25) | C25: =COUNTIFS(Bets!B$8:B$507,A25,Bets!L$8:L$507,"W") | D25: =COUNTIFS(Bets!B$8:B$507,A25,Bets!L$8:L$507,"L") | E25: =COUNTIFS(Bets!B$8:B$507,A25,Bets!L$8:L$507,"P") | F25: =IF((C25+D25)=0,"—",C25/(C25+D25)) | G25: =SUMIF(Bets!B$8:B$507,A25,Bets!N$8:N$507) | H25: =SUMIF(Bets!B$8:B$507,A25,Bets!O$8:O$507)
A26: 7 | B26: =COUNTIF(Bets!B$8:B$507,A26) | C26: =COUNTIFS(Bets!B$8:B$507,A26,Bets!L$8:L$507,"W") | D26: =COUNTIFS(Bets!B$8:B$507,A26,Bets!L$8:L$507,"L") | E26: =COUNTIFS(Bets!B$8:B$507,A26,Bets!L$8:L$507,"P") | F26: =IF((C26+D26)=0,"—",C26/(C26+D26)) | G26: =SUMIF(Bets!B$8:B$507,A26,Bets!N$8:N$507) | H26: =SUMIF(Bets!B$8:B$507,A26,Bets!O$8:O$507)
A27: 8 | B27: =COUNTIF(Bets!B$8:B$507,A27) | C27: =COUNTIFS(Bets!B$8:B$507,A27,Bets!L$8:L$507,"W") | D27: =COUNTIFS(Bets!B$8:B$507,A27,Bets!L$8:L$507,"L") | E27: =COUNTIFS(Bets!B$8:B$507,A27,Bets!L$8:L$507,"P") | F27: =IF((C27+D27)=0,"—",C27/(C27+D27)) | G27: =SUMIF(Bets!B$8:B$507,A27,Bets!N$8:N$507) | H27: =SUMIF(Bets!B$8:B$507,A27,Bets!O$8:O$507)
A28: 9 | B28: =COUNTIF(Bets!B$8:B$507,A28) | C28: =COUNTIFS(Bets!B$8:B$507,A28,Bets!L$8:L$507,"W") | D28: =COUNTIFS(Bets!B$8:B$507,A28,Bets!L$8:L$507,"L") | E28: =COUNTIFS(Bets!B$8:B$507,A28,Bets!L$8:L$507,"P") | F28: =IF((C28+D28)=0,"—",C28/(C28+D28)) | G28: =SUMIF(Bets!B$8:B$507,A28,Bets!N$8:N$507) | H28: =SUMIF(Bets!B$8:B$507,A28,Bets!O$8:O$507)
A29: 10 | B29: =COUNTIF(Bets!B$8:B$507,A29) | C29: =COUNTIFS(Bets!B$8:B$507,A29,Bets!L$8:L$507,"W") | D29: =COUNTIFS(Bets!B$8:B$507,A29,Bets!L$8:L$507,"L") | E29: =COUNTIFS(Bets!B$8:B$507,A29,Bets!L$8:L$507,"P") | F29: =IF((C29+D29)=0,"—",C29/(C29+D29)) | G29: =SUMIF(Bets!B$8:B$507,A29,Bets!N$8:N$507) | H29: =SUMIF(Bets!B$8:B$507,A29,Bets!O$8:O$507)
A30: 11 | B30: =COUNTIF(Bets!B$8:B$507,A30) | C30: =COUNTIFS(Bets!B$8:B$507,A30,Bets!L$8:L$507,"W") | D30: =COUNTIFS(Bets!B$8:B$507,A30,Bets!L$8:L$507,"L") | E30: =COUNTIFS(Bets!B$8:B$507,A30,Bets!L$8:L$507,"P") | F30: =IF((C30+D30)=0,"—",C30/(C30+D30)) | G30: =SUMIF(Bets!B$8:B$507,A30,Bets!N$8:N$507) | H30: =SUMIF(Bets!B$8:B$507,A30,Bets!O$8:O$507)
A31: 12 | B31: =COUNTIF(Bets!B$8:B$507,A31) | C31: =COUNTIFS(Bets!B$8:B$507,A31,Bets!L$8:L$507,"W") | D31: =COUNTIFS(Bets!B$8:B$507,A31,Bets!L$8:L$507,"L") | E31: =COUNTIFS(Bets!B$8:B$507,A31,Bets!L$8:L$507,"P") | F31: =IF((C31+D31)=0,"—",C31/(C31+D31)) | G31: =SUMIF(Bets!B$8:B$507,A31,Bets!N$8:N$507) | H31: =SUMIF(Bets!B$8:B$507,A31,Bets!O$8:O$507)
... A37: 18 | B37: =COUNTIF(Bets!B$8:B$507,A37) | C37: =COUNTIFS(Bets!B$8:B$507,A37,Bets!L$8:L$507,"W") | D37: =COUNTIFS(Bets!B$8:B$507,A37,Bets!L$8:L$507,"L") | E37: =COUNTIFS(Bets!B$8:B$507,A37,Bets!L$8:L$507,"P") | F37: =IF((C37+D37)=0,"—",C37/(C37+D37)) | G37: =SUMIF(Bets!B$8:B$507,A37,Bets!N$8:N$507) | H37: =SUMIF(Bets!B$8:B$507,A37,Bets!O$8:O$507)
A38: TOTAL | B38: =SUM(B20:B37) | C38: =SUM(C20:C37) | D38: =SUM(D20:D37) | E38: =SUM(E20:E37) | F38: =IF((C38+D38)=0,"—",C38/(C38+D38)) | G38: =SUM(G20:G37) | H38: =SUM(H20:H37)
A40: RECORD BY BET TYPE
A41: Type | B41: Bets | C41: W | D41: L | E41: P | F41: Win % | G41: Units | H41: Profit $
A42: Spread | B42: =COUNTIF(Bets!F$8:F$507,A42) | C42: =COUNTIFS(Bets!F$8:F$507,A42,Bets!L$8:L$507,"W") | D42: =COUNTIFS(Bets!F$8:F$507,A42,Bets!L$8:L$507,"L") | E42: =COUNTIFS(Bets!F$8:F$507,A42,Bets!L$8:L$507,"P") | F42: =IF((C42+D42)=0,"—",C42/(C42+D42)) | G42: =SUMIF(Bets!F$8:F$507,A42,Bets!N$8:N$507) | H42: =SUMIF(Bets!F$8:F$507,A42,Bets!O$8:O$507)
A43: Moneyline | B43: =COUNTIF(Bets!F$8:F$507,A43) | C43: =COUNTIFS(Bets!F$8:F$507,A43,Bets!L$8:L$507,"W") | D43: =COUNTIFS(Bets!F$8:F$507,A43,Bets!L$8:L$507,"L") | E43: =COUNTIFS(Bets!F$8:F$507,A43,Bets!L$8:L$507,"P") | F43: =IF((C43+D43)=0,"—",C43/(C43+D43)) | G43: =SUMIF(Bets!F$8:F$507,A43,Bets!N$8:N$507) | H43: =SUMIF(Bets!F$8:F$507,A43,Bets!O$8:O$507)
A44: Total | B44: =COUNTIF(Bets!F$8:F$507,A44) | C44: =COUNTIFS(Bets!F$8:F$507,A44,Bets!L$8:L$507,"W") | D44: =COUNTIFS(Bets!F$8:F$507,A44,Bets!L$8:L$507,"L") | E44: =COUNTIFS(Bets!F$8:F$507,A44,Bets!L$8:L$507,"P") | F44: =IF((C44+D44)=0,"—",C44/(C44+D44)) | G44: =SUMIF(Bets!F$8:F$507,A44,Bets!N$8:N$507) | H44: =SUMIF(Bets!F$8:F$507,A44,Bets!O$8:O$507)
A45: Player Prop | B45: =COUNTIF(Bets!F$8:F$507,A45) | C45: =COUNTIFS(Bets!F$8:F$507,A45,Bets!L$8:L$507,"W") | D45: =COUNTIFS(Bets!F$8:F$507,A45,Bets!L$8:L$507,"L") | E45: =COUNTIFS(Bets!F$8:F$507,A45,Bets!L$8:L$507,"P") | F45: =IF((C45+D45)=0,"—",C45/(C45+D45)) | G45: =SUMIF(Bets!F$8:F$507,A45,Bets!N$8:N$507) | H45: =SUMIF(Bets!F$8:F$507,A45,Bets!O$8:O$507)
A46: Team Prop | B46: =COUNTIF(Bets!F$8:F$507,A46) | C46: =COUNTIFS(Bets!F$8:F$507,A46,Bets!L$8:L$507,"W") | D46: =COUNTIFS(Bets!F$8:F$507,A46,Bets!L$8:L$507,"L") | E46: =COUNTIFS(Bets!F$8:F$507,A46,Bets!L$8:L$507,"P") | F46: =IF((C46+D46)=0,"—",C46/(C46+D46)) | G46: =SUMIF(Bets!F$8:F$507,A46,Bets!N$8:N$507) | H46: =SUMIF(Bets!F$8:F$507,A46,Bets!O$8:O$507)
A47: Parlay | B47: =COUNTIF(Bets!F$8:F$507,A47) | C47: =COUNTIFS(Bets!F$8:F$507,A47,Bets!L$8:L$507,"W") | D47: =COUNTIFS(Bets!F$8:F$507,A47,Bets!L$8:L$507,"L") | E47: =COUNTIFS(Bets!F$8:F$507,A47,Bets!L$8:L$507,"P") | F47: =IF((C47+D47)=0,"—",C47/(C47+D47)) | G47: =SUMIF(Bets!F$8:F$507,A47,Bets!N$8:N$507) | H47: =SUMIF(Bets!F$8:F$507,A47,Bets!O$8:O$507)
A48: Teaser | B48: =COUNTIF(Bets!F$8:F$507,A48) | C48: =COUNTIFS(Bets!F$8:F$507,A48,Bets!L$8:L$507,"W") | D48: =COUNTIFS(Bets!F$8:F$507,A48,Bets!L$8:L$507,"L") | E48: =COUNTIFS(Bets!F$8:F$507,A48,Bets!L$8:L$507,"P") | F48: =IF((C48+D48)=0,"—",C48/(C48+D48)) | G48: =SUMIF(Bets!F$8:F$507,A48,Bets!N$8:N$507) | H48: =SUMIF(Bets!F$8:F$507,A48,Bets!O$8:O$507)
A49: Future | B49: =COUNTIF(Bets!F$8:F$507,A49) | C49: =COUNTIFS(Bets!F$8:F$507,A49,Bets!L$8:L$507,"W") | D49: =COUNTIFS(Bets!F$8:F$507,A49,Bets!L$8:L$507,"L") | E49: =COUNTIFS(Bets!F$8:F$507,A49,Bets!L$8:L$507,"P") | F49: =IF((C49+D49)=0,"—",C49/(C49+D49)) | G49: =SUMIF(Bets!F$8:F$507,A49,Bets!N$8:N$507) | H49: =SUMIF(Bets!F$8:F$507,A49,Bets!O$8:O$507)
A50: Other | B50: =COUNTIF(Bets!F$8:F$507,A50) | C50: =COUNTIFS(Bets!F$8:F$507,A50,Bets!L$8:L$507,"W") | D50: =COUNTIFS(Bets!F$8:F$507,A50,Bets!L$8:L$507,"L") | E50: =COUNTIFS(Bets!F$8:F$507,A50,Bets!L$8:L$507,"P") | F50: =IF((C50+D50)=0,"—",C50/(C50+D50)) | G50: =SUMIF(Bets!F$8:F$507,A50,Bets!N$8:N$507) | H50: =SUMIF(Bets!F$8:F$507,A50,Bets!O$8:O$507)
A53: OPEN TICKETS (not yet graded)
...

Sheet Bets
A1: BET LOG • TEMPLATE
A2: Log After Dark / Packet / Gameday leans only. Status W, L, P, or PENDING.
A3: Source column Q: After Dark | Packet Board | Packet Best 10 | Packet Prop | Gameday. PASS = do not log.
A4: Settings!B3
A7: ID | B7: Week | C7: Date | D7: Game | E7: Play | F7: Type | G7: Odds | H7: Book | I7: Stake $ | J7: Units | K7: Result Score | L7: Status | M7: Payout $ | N7: Units Won | O7: Profit $ | P7: League | Q7: Source
A8: =IF(C8="","",ROW()-7) | M8: =IF(OR(L8="",L8="PENDING"),"",IF(L8="P",I8,IF(L8="L",0,IF(G8<0,I8+I8*100/ABS(G8),I8+I8*G8/100)))) | N8: =IF(OR(L8="",L8="PENDING"),"",IF(L8="P",0,IF(L8="L",-J8,IF(G8<0,J8*100/ABS(G8),J8*G8/100)))) | O8: =IF(OR(L8="",L8="PENDING"),"",IF(L8="P",0,M8-I8))
A9: =IF(C9="","",ROW()-7) | M9: =IF(OR(L9="",L9="PENDING"),"",IF(L9="P",I9,IF(L9="L",0,IF(G9<0,I9+I9*100/ABS(G9),I9+I9*G9/100)))) | N9: =IF(OR(L9="",L9="PENDING"),"",IF(L9="P",0,IF(L9="L",-J9,IF(G9<0,J9*100/ABS(G9),J9*G9/100)))) | O9: =IF(OR(L9="",L9="PENDING"),"",IF(L9="P",0,M9-I9))
A10: =IF(C10="","",ROW()-7) | M10: =IF(OR(L10="",L10="PENDING"),"",IF(L10="P",I10,IF(L10="L",0,IF(G10<0,I10+I10*100/ABS(G10),I10+I10*G10/100)))) | N10: =IF(OR(L10="",L10="PENDING"),"",IF(L10="P",0,IF(L10="L",-J10,IF(G10<0,J10*100/ABS(G10),J10*G10/100)))) | O10: =IF(OR(L10="",L10="PENDING"),"",IF(L10="P",0,M10-I10))
A11: =IF(C11="","",ROW()-7) | M11: =IF(OR(L11="",L11="PENDING"),"",IF(L11="P",I11,IF(L11="L",0,IF(G11<0,I11+I11*100/ABS(G11),I11+I11*G11/100)))) | N11: =IF(OR(L11="",L11="PENDING"),"",IF(L11="P",0,IF(L11="L",-J11,IF(G11<0,J11*100/ABS(G11),J11*G11/100)))) | O11: =IF(OR(L11="",L11="PENDING"),"",IF(L11="P",0,M11-I11))
A12: =IF(C12="","",ROW()-7) | M12: =IF(OR(L12="",L12="PENDING"),"",IF(L12="P",I12,IF(L12="L",0,IF(G12<0,I12+I12*100/ABS(G12),I12+I12*G12/100)))) | N12: =IF(OR(L12="",L12="PENDING"),"",IF(L12="P",0,IF(L12="L",-J12,IF(G12<0,J12*100/ABS(G12),J12*G12/100)))) | O12: =IF(OR(L12="",L12="PENDING"),"",IF(L12="P",0,M12-I12))
A13: =IF(C13="","",ROW()-7) | M13: =IF(OR(L13="",L13="PENDING"),"",IF(L13="P",I13,IF(L13="L",0,IF(G13<0,I13+I13*100/ABS(G13),I13+I13*G13/100)))) | N13: =IF(OR(L13="",L13="PENDING"),"",IF(L13="P",0,IF(L13="L",-J13,IF(G13<0,J13*100/ABS(G13),J13*G13/100)))) | O13: =IF(OR(L13="",L13="PENDING"),"",IF(L13="P",0,M13-I13))
A14: =IF(C14="","",ROW()-7) | M14: =IF(OR(L14="",L14="PENDING"),"",IF(L14="P",I14,IF(L14="L",0,IF(G14<0,I14+I14*100/ABS(G14),I14+I14*G14/100)))) | N14: =IF(OR(L14="",L14="PENDING"),"",IF(L14="P",0,IF(L14="L",-J14,IF(G14<0,J14*100/ABS(G14),J14*G14/100)))) | O14: =IF(OR(L14="",L14="PENDING"),"",IF(L14="P",0,M14-I14))
A15: =IF(C15="","",ROW()-7) | M15: =IF(OR(L15="",L15="PENDING"),"",IF(L15="P",I15,IF(L15="L",0,IF(G15<0,I15+I15*100/ABS(G15),I15+I15*G15/100)))) | N15: =IF(OR(L15="",L15="PENDING"),"",IF(L15="P",0,IF(L15="L",-J15,IF(G15<0,J15*100/ABS(G15),J15*G15/100)))) | O15: =IF(OR(L15="",L15="PENDING"),"",IF(L15="P",0,M15-I15))
A16: =IF(C16="","",ROW()-7) | M16: =IF(OR(L16="",L16="PENDING"),"",IF(L16="P",I16,IF(L16="L",0,IF(G16<0,I16+I16*100/ABS(G16),I16+I16*G16/100)))) | N16: =IF(OR(L16="",L16="PENDING"),"",IF(L16="P",0,IF(L16="L",-J16,IF(G16<0,J16*100/ABS(G16),J16*G16/100)))) | O16: =IF(OR(L16="",L16="PENDING"),"",IF(L16="P",0,M16-I16))
A17: =IF(C17="","",ROW()-7) | M17: =IF(OR(L17="",L17="PENDING"),"",IF(L17="P",I17,IF(L17="L",0,IF(G17<0,I17+I17*100/ABS(G17),I17+I17*G17/100)))) | N17: =IF(OR(L17="",L17="PENDING"),"",IF(L17="P",0,IF(L17="L",-J17,IF(G17<0,J17*100/ABS(G17),J17*G17/100)))) | O17: =IF(OR(L17="",L17="PENDING"),"",IF(L17="P",0,M17-I17))
A18: =IF(C18="","",ROW()-7) | M18: =IF(OR(L18="",L18="PENDING"),"",IF(L18="P",I18,IF(L18="L",0,IF(G18<0,I18+I18*100/ABS(G18),I18+I18*G18/100)))) | N18: =IF(OR(L18="",L18="PENDING"),"",IF(L18="P",0,IF(L18="L",-J18,IF(G18<0,J18*100/ABS(G18),J18*G18/100)))) | O18: =IF(OR(L18="",L18="PENDING"),"",IF(L18="P",0,M18-I18))
A19: =IF(C19="","",ROW()-7) | M19: =IF(OR(L19="",L19="PENDING"),"",IF(L19="P",I19,IF(L19="L",0,IF(G19<0,I19+I19*100/ABS(G19),I19+I19*G19/100)))) | N19: =IF(OR(L19="",L19="PENDING"),"",IF(L19="P",0,IF(L19="L",-J19,IF(G19<0,J19*100/ABS(G19),J19*G19/100)))) | O19: =IF(OR(L19="",L19="PENDING"),"",IF(L19="P",0,M19-I19))
... A26: =IF(C26="","",ROW()-7) | M26: =IF(OR(L26="",L26="PENDING"),"",IF(L26="P",I26,IF(L26="L",0,IF(G26<0,I26+I26*100/ABS(G26),I26+I26*G26/100)))) | N26: =IF(OR(L26="",L26="PENDING"),"",IF(L26="P",0,IF(L26="L",-J26,IF(G26<0,J26*100/ABS(G26),J26*G26/100)))) | O26: =IF(OR(L26="",L26="PENDING"),"",IF(L26="P",0,M26-I26))
A27: 20 | M27: =IF(OR(L27="",L27="PENDING"),"",IF(L27="P",I27,IF(L27="L",0,IF(G27<0,I27+I27*100/ABS(G27),I27+I27*G27/100)))) | N27: =IF(OR(L27="",L27="PENDING"),"",IF(L27="P",0,IF(L27="L",-J27,IF(G27<0,J27*100/ABS(G27),J27*G27/100)))) | O27: =IF(OR(L27="",L27="PENDING"),"",IF(L27="P",0,M27-I27))
A28: 21 | M28: =IF(OR(L28="",L28="PENDING"),"",IF(L28="P",I28,IF(L28="L",0,IF(G28<0,I28+I28*100/ABS(G28),I28+I28*G28/100)))) | N28: =IF(OR(L28="",L28="PENDING"),"",IF(L28="P",0,IF(L28="L",-J28,IF(G28<0,J28*100/ABS(G28),J28*G28/100)))) | O28: =IF(OR(L28="",L28="PENDING"),"",IF(L28="P",0,M28-I28))
A29: 22 | M29: =IF(OR(L29="",L29="PENDING"),"",IF(L29="P",I29,IF(L29="L",0,IF(G29<0,I29+I29*100/ABS(G29),I29+I29*G29/100)))) | N29: =IF(OR(L29="",L29="PENDING"),"",IF(L29="P",0,IF(L29="L",-J29,IF(G29<0,J29*100/ABS(G29),J29*G29/100)))) | O29: =IF(OR(L29="",L29="PENDING"),"",IF(L29="P",0,M29-I29))
A30: 23 | M30: =IF(OR(L30="",L30="PENDING"),"",IF(L30="P",I30,IF(L30="L",0,IF(G30<0,I30+I30*100/ABS(G30),I30+I30*G30/100)))) | N30: =IF(OR(L30="",L30="PENDING"),"",IF(L30="P",0,IF(L30="L",-J30,IF(G30<0,J30*100/ABS(G30),J30*G30/100)))) | O30: =IF(OR(L30="",L30="PENDING"),"",IF(L30="P",0,M30-I30))
A31: 24 | M31: =IF(OR(L31="",L31="PENDING"),"",IF(L31="P",I31,IF(L31="L",0,IF(G31<0,I31+I31*100/ABS(G31),I31+I31*G31/100)))) | N31: =IF(OR(L31="",L31="PENDING"),"",IF(L31="P",0,IF(L31="L",-J31,IF(G31<0,J31*100/ABS(G31),J31*G31/100)))) | O31: =IF(OR(L31="",L31="PENDING"),"",IF(L31="P",0,M31-I31))
A32: 25 | M32: =IF(OR(L32="",L32="PENDING"),"",IF(L32="P",I32,IF(L32="L",0,IF(G32<0,I32+I32*100/ABS(G32),I32+I32*G32/100)))) | N32: =IF(OR(L32="",L32="PENDING"),"",IF(L32="P",0,IF(L32="L",-J32,IF(G32<0,J32*100/ABS(G32),J32*G32/100)))) | O32: =IF(OR(L32="",L32="PENDING"),"",IF(L32="P",0,M32-I32))
A33: 26 | M33: =IF(OR(L33="",L33="PENDING"),"",IF(L33="P",I33,IF(L33="L",0,IF(G33<0,I33+I33*100/ABS(G33),I33+I33*G33/100)))) | N33: =IF(OR(L33="",L33="PENDING"),"",IF(L33="P",0,IF(L33="L",-J33,IF(G33<0,J33*100/ABS(G33),J33*G33/100)))) | O33: =IF(OR(L33="",L33="PENDING"),"",IF(L33="P",0,M33-I33))
A34: 27 | M34: =IF(OR(L34="",L34="PENDING"),"",IF(L34="P",I34,IF(L34="L",0,IF(G34<0,I34+I34*100/ABS(G34),I34+I34*G34/100)))) | N34: =IF(OR(L34="",L34="PENDING"),"",IF(L34="P",0,IF(L34="L",-J34,IF(G34<0,J34*100/ABS(G34),J34*G34/100)))) | O34: =IF(OR(L34="",L34="PENDING"),"",IF(L34="P",0,M34-I34))
A35: 28 | M35: =IF(OR(L35="",L35="PENDING"),"",IF(L35="P",I35,IF(L35="L",0,IF(G35<0,I35+I35*100/ABS(G35),I35+I35*G35/100)))) | N35: =IF(OR(L35="",L35="PENDING"),"",IF(L35="P",0,IF(L35="L",-J35,IF(G35<0,J35*100/ABS(G35),J35*G35/100)))) | O35: =IF(OR(L35="",L35="PENDING"),"",IF(L35="P",0,M35-I35))
A36: =IF(C36="","",ROW()-7) | M36: =IF(OR(L36="",L36="PENDING"),"",IF(L36="P",I36,IF(L36="L",0,IF(G36<0,I36+I36*100/ABS(G36),I36+I36*G36/100)))) | N36: =IF(OR(L36="",L36="PENDING"),"",IF(L36="P",0,IF(L36="L",-J36,IF(G36<0,J36*100/ABS(G36),J36*G36/100)))) | O36: =IF(OR(L36="",L36="PENDING"),"",IF(L36="P",0,M36-I36))
A37: =IF(C37="","",ROW()-7) | M37: =IF(OR(L37="",L37="PENDING"),"",IF(L37="P",I37,IF(L37="L",0,IF(G37<0,I37+I37*100/ABS(G37),I37+I37*G37/100)))) | N37: =IF(OR(L37="",L37="PENDING"),"",IF(L37="P",0,IF(L37="L",-J37,IF(G37<0,J37*100/ABS(G37),J37*G37/100)))) | O37: =IF(OR(L37="",L37="PENDING"),"",IF(L37="P",0,M37-I37))
A38: =IF(C38="","",ROW()-7) | M38: =IF(OR(L38="",L38="PENDING"),"",IF(L38="P",I38,IF(L38="L",0,IF(G38<0,I38+I38*100/ABS(G38),I38+I38*G38/100)))) | N38: =IF(OR(L38="",L38="PENDING"),"",IF(L38="P",0,IF(L38="L",-J38,IF(G38<0,J38*100/ABS(G38),J38*G38/100)))) | O38: =IF(OR(L38="",L38="PENDING"),"",IF(L38="P",0,M38-I38))
A39: =IF(C39="","",ROW()-7) | M39: =IF(OR(L39="",L39="PENDING"),"",IF(L39="P",I39,IF(L39="L",0,IF(G39<0,I39+I39*100/ABS(G39),I39+I39*G39/100)))) | N39: =IF(OR(L39="",L39="PENDING"),"",IF(L39="P",0,IF(L39="L",-J39,IF(G39<0,J39*100/ABS(G39),J39*G39/100)))) | O39: =IF(OR(L39="",L39="PENDING"),"",IF(L39="P",0,M39-I39))
A40: =IF(C40="","",ROW()-7) | M40: =IF(OR(L40="",L40="PENDING"),"",IF(L40="P",I40,IF(L40="L",0,IF(G40<0,I40+I40*100/ABS(G40),I40+I40*G40/100)))) | N40: =IF(OR(L40="",L40="PENDING"),"",IF(L40="P",0,IF(L40="L",-J40,IF(G40<0,J40*100/ABS(G40),J40*G40/100)))) | O40: =IF(OR(L40="",L40="PENDING"),"",IF(L40="P",0,M40-I40))
A41: =IF(C41="","",ROW()-7) | M41: =IF(OR(L41="",L41="PENDING"),"",IF(L41="P",I41,IF(L41="L",0,IF(G41<0,I41+I41*100/ABS(G41),I41+I41*G41/100)))) | N41: =IF(OR(L41="",L41="PENDING"),"",IF(L41="P",0,IF(L41="L",-J41,IF(G41<0,J41*100/ABS(G41),J41*G41/100)))) | O41: =IF(OR(L41="",L41="PENDING"),"",IF(L41="P",0,M41-I41))
A42: =IF(C42="","",ROW()-7) | M42: =IF(OR(L42="",L42="PENDING"),"",IF(L42="P",I42,IF(L42="L",0,IF(G42<0,I42+I42*100/ABS(G42),I42+I42*G42/100)))) | N42: =IF(OR(L42="",L42="PENDING"),"",IF(L42="P",0,IF(L42="L",-J42,IF(G42<0,J42*100/ABS(G42),J42*G42/100)))) | O42: =IF(OR(L42="",L42="PENDING"),"",IF(L42="P",0,M42-I42))
A43: =IF(C43="","",ROW()-7) | M43: =IF(OR(L43="",L43="PENDING"),"",IF(L43="P",I43,IF(L43="L",0,IF(G43<0,I43+I43*100/ABS(G43),I43+I43*G43/100)))) | N43: =IF(OR(L43="",L43="PENDING"),"",IF(L43="P",0,IF(L43="L",-J43,IF(G43<0,J43*100/ABS(G43),J43*G43/100)))) | O43: =IF(OR(L43="",L43="PENDING"),"",IF(L43="P",0,M43-I43))
A44: =IF(C44="","",ROW()-7) | M44: =IF(OR(L44="",L44="PENDING"),"",IF(L44="P",I44,IF(L44="L",0,IF(G44<0,I44+I44*100/ABS(G44),I44+I44*G44/100)))) | N44: =IF(OR(L44="",L44="PENDING"),"",IF(L44="P",0,IF(L44="L",-J44,IF(G44<0,J44*100/ABS(G44),J44*G44/100)))) | O44: =IF(OR(L44="",L44="PENDING"),"",IF(L44="P",0,M44-I44))
A45: =IF(C45="","",ROW()-7) | M45: =IF(OR(L45="",L45="PENDING"),"",IF(L45="P",I45,IF(L45="L",0,IF(G45<0,I45+I45*100/ABS(G45),I45+I45*G45/100)))) | N45: =IF(OR(L45="",L45="PENDING"),"",IF(L45="P",0,IF(L45="L",-J45,IF(G45<0,J45*100/ABS(G45),J45*G45/100)))) | O45: =IF(OR(L45="",L45="PENDING"),"",IF(L45="P",0,M45-I45))
A46: =IF(C46="","",ROW()-7) | M46: =IF(OR(L46="",L46="PENDING"),"",IF(L46="P",I46,IF(L46="L",0,IF(G46<0,I46+I46*100/ABS(G46),I46+I46*G46/100)))) | N46: =IF(OR(L46="",L46="PENDING"),"",IF(L46="P",0,IF(L46="L",-J46,IF(G46<0,J46*100/ABS(G46),J46*G46/100)))) | O46: =IF(OR(L46="",L46="PENDING"),"",IF(L46="P",0,M46-I46))
A47: =IF(C47="","",ROW()-7) | M47: =IF(OR(L47="",L47="PENDING"),"",IF(L47="P",I47,IF(L47="L",0,IF(G47<0,I47+I47*100/ABS(G47),I47+I47*G47/100)))) | N47: =IF(OR(L47="",L47="PENDING"),"",IF(L47="P",0,IF(L47="L",-J47,IF(G47<0,J47*100/ABS(G47),J47*G47/100)))) | O47: =IF(OR(L47="",L47="PENDING"),"",IF(L47="P",0,M47-I47))
... A507: =IF(C507="","",ROW()-7) | M507: =IF(OR(L507="",L507="PENDING"),"",IF(L507="P",I507,IF(L507="L",0,IF(G507<0,I507+I507*100/ABS(G507),I507+I507*G507/100)))) | N507: =IF(OR(L507="",L507="PENDING"),"",IF(L507="P",0,IF(L507="L",-J507,IF(G507<0,J507*100/ABS(G507),J507*G507/100)))) | O507: =IF(OR(L507="",L507="PENDING"),"",IF(L507="P",0,M507-I507))

Sheet Futures
A1: FUTURES • FRD (rarely used)
A2: Super Bowl, division, win totals, awards. Stay here until the market settles.
A4: ID | B4: Market | C4: Pick | D4: Odds | E4: Book | F4: Date In | G4: Stake $ | H4: Units | I4: Status | J4: Payout $ | K4: Units Won | L4: Profit $
A5: =IF(B5="","",ROW()-4) | J5: =IF(OR(I5="",I5="PENDING"),"",IF(I5="P",G5,IF(I5="L",0,IF(D5<0,G5+G5*100/ABS(D5),G5+G5*D5/100)))) | K5: =IF(OR(I5="",I5="PENDING"),"",IF(I5="P",0,IF(I5="L",-H5,IF(D5<0,H5*100/ABS(D5),H5*D5/100)))) | L5: =IF(OR(I5="",I5="PENDING"),"",IF(I5="P",0,J5-G5))
A6: =IF(B6="","",ROW()-4) | J6: =IF(OR(I6="",I6="PENDING"),"",IF(I6="P",G6,IF(I6="L",0,IF(D6<0,G6+G6*100/ABS(D6),G6+G6*D6/100)))) | K6: =IF(OR(I6="",I6="PENDING"),"",IF(I6="P",0,IF(I6="L",-H6,IF(D6<0,H6*100/ABS(D6),H6*D6/100)))) | L6: =IF(OR(I6="",I6="PENDING"),"",IF(I6="P",0,J6-G6))
A7: =IF(B7="","",ROW()-4) | J7: =IF(OR(I7="",I7="PENDING"),"",IF(I7="P",G7,IF(I7="L",0,IF(D7<0,G7+G7*100/ABS(D7),G7+G7*D7/100)))) | K7: =IF(OR(I7="",I7="PENDING"),"",IF(I7="P",0,IF(I7="L",-H7,IF(D7<0,H7*100/ABS(D7),H7*D7/100)))) | L7: =IF(OR(I7="",I7="PENDING"),"",IF(I7="P",0,J7-G7))
A8: =IF(B8="","",ROW()-4) | J8: =IF(OR(I8="",I8="PENDING"),"",IF(I8="P",G8,IF(I8="L",0,IF(D8<0,G8+G8*100/ABS(D8),G8+G8*D8/100)))) | K8: =IF(OR(I8="",I8="PENDING"),"",IF(I8="P",0,IF(I8="L",-H8,IF(D8<0,H8*100/ABS(D8),H8*D8/100)))) | L8: =IF(OR(I8="",I8="PENDING"),"",IF(I8="P",0,J8-G8))
A9: =IF(B9="","",ROW()-4) | J9: =IF(OR(I9="",I9="PENDING"),"",IF(I9="P",G9,IF(I9="L",0,IF(D9<0,G9+G9*100/ABS(D9),G9+G9*D9/100)))) | K9: =IF(OR(I9="",I9="PENDING"),"",IF(I9="P",0,IF(I9="L",-H9,IF(D9<0,H9*100/ABS(D9),H9*D9/100)))) | L9: =IF(OR(I9="",I9="PENDING"),"",IF(I9="P",0,J9-G9))
A10: =IF(B10="","",ROW()-4) | J10: =IF(OR(I10="",I10="PENDING"),"",IF(I10="P",G10,IF(I10="L",0,IF(D10<0,G10+G10*100/ABS(D10),G10+G10*D10/100)))) | K10: =IF(OR(I10="",I10="PENDING"),"",IF(I10="P",0,IF(I10="L",-H10,IF(D10<0,H10*100/ABS(D10),H10*D10/100)))) | L10: =IF(OR(I10="",I10="PENDING"),"",IF(I10="P",0,J10-G10))
A11: =IF(B11="","",ROW()-4) | J11: =IF(OR(I11="",I11="PENDING"),"",IF(I11="P",G11,IF(I11="L",0,IF(D11<0,G11+G11*100/ABS(D11),G11+G11*D11/100)))) | K11: =IF(OR(I11="",I11="PENDING"),"",IF(I11="P",0,IF(I11="L",-H11,IF(D11<0,H11*100/ABS(D11),H11*D11/100)))) | L11: =IF(OR(I11="",I11="PENDING"),"",IF(I11="P",0,J11-G11))
A12: =IF(B12="","",ROW()-4) | J12: =IF(OR(I12="",I12="PENDING"),"",IF(I12="P",G12,IF(I12="L",0,IF(D12<0,G12+G12*100/ABS(D12),G12+G12*D12/100)))) | K12: =IF(OR(I12="",I12="PENDING"),"",IF(I12="P",0,IF(I12="L",-H12,IF(D12<0,H12*100/ABS(D12),H12*D12/100)))) | L12: =IF(OR(I12="",I12="PENDING"),"",IF(I12="P",0,J12-G12))
A13: =IF(B13="","",ROW()-4) | J13: =IF(OR(I13="",I13="PENDING"),"",IF(I13="P",G13,IF(I13="L",0,IF(D13<0,G13+G13*100/ABS(D13),G13+G13*D13/100)))) | K13: =IF(OR(I13="",I13="PENDING"),"",IF(I13="P",0,IF(I13="L",-H13,IF(D13<0,H13*100/ABS(D13),H13*D13/100)))) | L13: =IF(OR(I13="",I13="PENDING"),"",IF(I13="P",0,J13-G13))
A14: =IF(B14="","",ROW()-4) | J14: =IF(OR(I14="",I14="PENDING"),"",IF(I14="P",G14,IF(I14="L",0,IF(D14<0,G14+G14*100/ABS(D14),G14+G14*D14/100)))) | K14: =IF(OR(I14="",I14="PENDING"),"",IF(I14="P",0,IF(I14="L",-H14,IF(D14<0,H14*100/ABS(D14),H14*D14/100)))) | L14: =IF(OR(I14="",I14="PENDING"),"",IF(I14="P",0,J14-G14))
A15: =IF(B15="","",ROW()-4) | J15: =IF(OR(I15="",I15="PENDING"),"",IF(I15="P",G15,IF(I15="L",0,IF(D15<0,G15+G15*100/ABS(D15),G15+G15*D15/100)))) | K15: =IF(OR(I15="",I15="PENDING"),"",IF(I15="P",0,IF(I15="L",-H15,IF(D15<0,H15*100/ABS(D15),H15*D15/100)))) | L15: =IF(OR(I15="",I15="PENDING"),"",IF(I15="P",0,J15-G15))
A16: =IF(B16="","",ROW()-4) | J16: =IF(OR(I16="",I16="PENDING"),"",IF(I16="P",G16,IF(I16="L",0,IF(D16<0,G16+G16*100/ABS(D16),G16+G16*D16/100)))) | K16: =IF(OR(I16="",I16="PENDING"),"",IF(I16="P",0,IF(I16="L",-H16,IF(D16<0,H16*100/ABS(D16),H16*D16/100)))) | L16: =IF(OR(I16="",I16="PENDING"),"",IF(I16="P",0,J16-G16))
... A54: =IF(B54="","",ROW()-4) | J54: =IF(OR(I54="",I54="PENDING"),"",IF(I54="P",G54,IF(I54="L",0,IF(D54<0,G54+G54*100/ABS(D54),G54+G54*D54/100)))) | K54: =IF(OR(I54="",I54="PENDING"),"",IF(I54="P",0,IF(I54="L",-H54,IF(D54<0,H54*100/ABS(D54),H54*D54/100)))) | L54: =IF(OR(I54="",I54="PENDING"),"",IF(I54="P",0,J54-G54))

Sheet Settings
A1: SETTINGS • FRD
A3: Unit size ($) | B3: 25 | C3: Paper unit for published leans. Not a real bankroll.
A5: Season | B5: 2026 NFL + CFB
A6: Bankroll start ($) | B6: 0 | C6: Optional. Leave 0 if you only track units.
A7: Default book | B7: FRD
A9: Status codes
A10: W = win L = loss P = push PENDING = not graded
A12: Type list (must match Dashboard rollup)
A13: Spread
A14: Moneyline
A15: Total
A16: Player Prop
A17: Team Prop
A18: Parlay
A19: Teaser
A20: Future
A21: Other
A22: Flyer tab | B22: Excluded from Dashboard

Sheet Notes
A1: NOTES • FRD
A3: Date | B3: Week | C3: Note
A4: Template | C4: Empty on purpose. Fill as you play.

Sheet Flyer
A1: THE FLYER • AFTER DARK LONG SHOTS • NOT IN THE PUBLISHED RECORD
A2: Optional long-shot log. Keep it off your published W-L if you want the same rule as FRD.
A3: Same columns as Bets. Source is always After Dark.
A7: ID | B7: Week | C7: Date | D7: Game | E7: Play | F7: Nickname | G7: Odds | H7: Book | I7: Stake $ | J7: Units | K7: Result Score | L7: Status | M7: Payout $ | N7: Units Won | O7: Profit $ | P7: League | Q7: Source
A8: =IF(C8="","",ROW()-7) | M8: =IF(OR(L8="",L8="PENDING"),"",IF(L8="P",I8,IF(L8="L",0,IF(G8<0,I8+I8*100/ABS(G8),I8+I8*G8/100)))) | N8: =IF(OR(L8="",L8="PENDING"),"",IF(L8="P",0,IF(L8="L",-J8,IF(G8<0,J8*100/ABS(G8),J8*G8/100)))) | O8: =IF(OR(L8="",L8="PENDING"),"",IF(L8="P",0,M8-I8))
A9: =IF(C9="","",ROW()-7) | M9: =IF(OR(L9="",L9="PENDING"),"",IF(L9="P",I9,IF(L9="L",0,IF(G9<0,I9+I9*100/ABS(G9),I9+I9*G9/100)))) | N9: =IF(OR(L9="",L9="PENDING"),"",IF(L9="P",0,IF(L9="L",-J9,IF(G9<0,J9*100/ABS(G9),J9*G9/100)))) | O9: =IF(OR(L9="",L9="PENDING"),"",IF(L9="P",0,M9-I9))
A10: =IF(C10="","",ROW()-7) | M10: =IF(OR(L10="",L10="PENDING"),"",IF(L10="P",I10,IF(L10="L",0,IF(G10<0,I10+I10*100/ABS(G10),I10+I10*G10/100)))) | N10: =IF(OR(L10="",L10="PENDING"),"",IF(L10="P",0,IF(L10="L",-J10,IF(G10<0,J10*100/ABS(G10),J10*G10/100)))) | O10: =IF(OR(L10="",L10="PENDING"),"",IF(L10="P",0,M10-I10))
A11: =IF(C11="","",ROW()-7) | M11: =IF(OR(L11="",L11="PENDING"),"",IF(L11="P",I11,IF(L11="L",0,IF(G11<0,I11+I11*100/ABS(G11),I11+I11*G11/100)))) | N11: =IF(OR(L11="",L11="PENDING"),"",IF(L11="P",0,IF(L11="L",-J11,IF(G11<0,J11*100/ABS(G11),J11*G11/100)))) | O11: =IF(OR(L11="",L11="PENDING"),"",IF(L11="P",0,M11-I11))
A12: =IF(C12="","",ROW()-7) | M12: =IF(OR(L12="",L12="PENDING"),"",IF(L12="P",I12,IF(L12="L",0,IF(G12<0,I12+I12*100/ABS(G12),I12+I12*G12/100)))) | N12: =IF(OR(L12="",L12="PENDING"),"",IF(L12="P",0,IF(L12="L",-J12,IF(G12<0,J12*100/ABS(G12),J12*G12/100)))) | O12: =IF(OR(L12="",L12="PENDING"),"",IF(L12="P",0,M12-I12))
A13: =IF(C13="","",ROW()-7) | M13: =IF(OR(L13="",L13="PENDING"),"",IF(L13="P",I13,IF(L13="L",0,IF(G13<0,I13+I13*100/ABS(G13),I13+I13*G13/100)))) | N13: =IF(OR(L13="",L13="PENDING"),"",IF(L13="P",0,IF(L13="L",-J13,IF(G13<0,J13*100/ABS(G13),J13*G13/100)))) | O13: =IF(OR(L13="",L13="PENDING"),"",IF(L13="P",0,M13-I13))
A14: =IF(C14="","",ROW()-7) | M14: =IF(OR(L14="",L14="PENDING"),"",IF(L14="P",I14,IF(L14="L",0,IF(G14<0,I14+I14*100/ABS(G14),I14+I14*G14/100)))) | N14: =IF(OR(L14="",L14="PENDING"),"",IF(L14="P",0,IF(L14="L",-J14,IF(G14<0,J14*100/ABS(G14),J14*G14/100)))) | O14: =IF(OR(L14="",L14="PENDING"),"",IF(L14="P",0,M14-I14))
A15: =IF(C15="","",ROW()-7) | M15: =IF(OR(L15="",L15="PENDING"),"",IF(L15="P",I15,IF(L15="L",0,IF(G15<0,I15+I15*100/ABS(G15),I15+I15*G15/100)))) | N15: =IF(OR(L15="",L15="PENDING"),"",IF(L15="P",0,IF(L15="L",-J15,IF(G15<0,J15*100/ABS(G15),J15*G15/100)))) | O15: =IF(OR(L15="",L15="PENDING"),"",IF(L15="P",0,M15-I15))
A16: =IF(C16="","",ROW()-7) | M16: =IF(OR(L16="",L16="PENDING"),"",IF(L16="P",I16,IF(L16="L",0,IF(G16<0,I16+I16*100/ABS(G16),I16+I16*G16/100)))) | N16: =IF(OR(L16="",L16="PENDING"),"",IF(L16="P",0,IF(L16="L",-J16,IF(G16<0,J16*100/ABS(G16),J16*G16/100)))) | O16: =IF(OR(L16="",L16="PENDING"),"",IF(L16="P",0,M16-I16))
A17: =IF(C17="","",ROW()-7) | M17: =IF(OR(L17="",L17="PENDING"),"",IF(L17="P",I17,IF(L17="L",0,IF(G17<0,I17+I17*100/ABS(G17),I17+I17*G17/100)))) | N17: =IF(OR(L17="",L17="PENDING"),"",IF(L17="P",0,IF(L17="L",-J17,IF(G17<0,J17*100/ABS(G17),J17*G17/100)))) | O17: =IF(OR(L17="",L17="PENDING"),"",IF(L17="P",0,M17-I17))
A18: =IF(C18="","",ROW()-7) | M18: =IF(OR(L18="",L18="PENDING"),"",IF(L18="P",I18,IF(L18="L",0,IF(G18<0,I18+I18*100/ABS(G18),I18+I18*G18/100)))) | N18: =IF(OR(L18="",L18="PENDING"),"",IF(L18="P",0,IF(L18="L",-J18,IF(G18<0,J18*100/ABS(G18),J18*G18/100)))) | O18: =IF(OR(L18="",L18="PENDING"),"",IF(L18="P",0,M18-I18))
A19: =IF(C19="","",ROW()-7) | M19: =IF(OR(L19="",L19="PENDING"),"",IF(L19="P",I19,IF(L19="L",0,IF(G19<0,I19+I19*100/ABS(G19),I19+I19*G19/100)))) | N19: =IF(OR(L19="",L19="PENDING"),"",IF(L19="P",0,IF(L19="L",-J19,IF(G19<0,J19*100/ABS(G19),J19*G19/100)))) | O19: =IF(OR(L19="",L19="PENDING"),"",IF(L19="P",0,M19-I19))
... A57: =IF(C57="","",ROW()-7) | M57: =IF(OR(L57="",L57="PENDING"),"",IF(L57="P",I57,IF(L57="L",0,IF(G57<0,I57+I57*100/ABS(G57),I57+I57*G57/100)))) | N57: =IF(OR(L57="",L57="PENDING"),"",IF(L57="P",0,IF(L57="L",-J57,IF(G57<0,J57*100/ABS(G57),J57*G57/100)))) | O57: =IF(OR(L57="",L57="PENDING"),"",IF(L57="P",0,M57-I57))
